[2025-07-12T04:17:03.266+0000] {local_task_job_runner.py:120} INFO - ::group::Pre task execution logs
[2025-07-12T04:17:03.316+0000] {taskinstance.py:2076} INFO - Dependencies all met for dep_context=non-requeueable deps ti=<TaskInstance: ml_pipeline.training_task scheduled__2025-07-11T00:00:00+00:00 [queued]>
[2025-07-12T04:17:03.331+0000] {taskinstance.py:2076} INFO - Dependencies all met for dep_context=requeueable deps ti=<TaskInstance: ml_pipeline.training_task scheduled__2025-07-11T00:00:00+00:00 [queued]>
[2025-07-12T04:17:03.332+0000] {taskinstance.py:2306} INFO - Starting attempt 1 of 1
[2025-07-12T04:17:03.353+0000] {taskinstance.py:2330} INFO - Executing <Task(BashOperator): training_task> on 2025-07-11 00:00:00+00:00
[2025-07-12T04:17:03.365+0000] {standard_task_runner.py:63} INFO - Started process 312 to run task
[2025-07-12T04:17:03.371+0000] {standard_task_runner.py:90} INFO - Running: ['***', 'tasks', 'run', 'ml_pipeline', 'training_task', 'scheduled__2025-07-11T00:00:00+00:00', '--job-id', '10', '--raw', '--subdir', 'DAGS_FOLDER/ml_pipeline.py', '--cfg-path', '/tmp/tmp3jenjivo']
[2025-07-12T04:17:03.375+0000] {standard_task_runner.py:91} INFO - Job 10: Subtask training_task
[2025-07-12T04:17:03.452+0000] {task_command.py:426} INFO - Running <TaskInstance: ml_pipeline.training_task scheduled__2025-07-11T00:00:00+00:00 [running]> on host 9c8ac9649d23
[2025-07-12T04:17:03.574+0000] {taskinstance.py:2648} INFO - Exporting env vars: AIRFLOW_CTX_DAG_OWNER='Ebrahim Emad' AIRFLOW_CTX_DAG_ID='ml_pipeline' AIRFLOW_CTX_TASK_ID='training_task' AIRFLOW_CTX_EXECUTION_DATE='2025-07-11T00:00:00+00:00' AIRFLOW_CTX_TRY_NUMBER='1' AIRFLOW_CTX_DAG_RUN_ID='scheduled__2025-07-11T00:00:00+00:00'
[2025-07-12T04:17:03.574+0000] {taskinstance.py:430} INFO - ::endgroup::
[2025-07-12T04:17:03.595+0000] {subprocess.py:63} INFO - Tmp dir root location: /tmp
[2025-07-12T04:17:03.596+0000] {subprocess.py:75} INFO - Running command: ['/usr/bin/bash', '-c', 'python /opt/***/scripts/code.py']
[2025-07-12T04:17:03.618+0000] {subprocess.py:86} INFO - Output:
[2025-07-12T04:17:07.818+0000] {subprocess.py:93} INFO - Traceback (most recent call last):
[2025-07-12T04:17:07.818+0000] {subprocess.py:93} INFO -   File "/opt/***/scripts/code.py", line 14, in <module>
[2025-07-12T04:17:07.819+0000] {subprocess.py:93} INFO -     df=pd.read_csv('../Data/churn-data.csv')
[2025-07-12T04:17:07.819+0000] {subprocess.py:93} INFO -   File "/home/***/.local/lib/python3.10/site-packages/pandas/io/parsers/readers.py", line 948, in read_csv
[2025-07-12T04:17:07.820+0000] {subprocess.py:93} INFO -     return _read(filepath_or_buffer, kwds)
[2025-07-12T04:17:07.820+0000] {subprocess.py:93} INFO -   File "/home/***/.local/lib/python3.10/site-packages/pandas/io/parsers/readers.py", line 611, in _read
[2025-07-12T04:17:07.820+0000] {subprocess.py:93} INFO -     parser = TextFileReader(filepath_or_buffer, **kwds)
[2025-07-12T04:17:07.820+0000] {subprocess.py:93} INFO -   File "/home/***/.local/lib/python3.10/site-packages/pandas/io/parsers/readers.py", line 1448, in __init__
[2025-07-12T04:17:07.821+0000] {subprocess.py:93} INFO -     self._engine = self._make_engine(f, self.engine)
[2025-07-12T04:17:07.821+0000] {subprocess.py:93} INFO -   File "/home/***/.local/lib/python3.10/site-packages/pandas/io/parsers/readers.py", line 1705, in _make_engine
[2025-07-12T04:17:07.821+0000] {subprocess.py:93} INFO -     self.handles = get_handle(
[2025-07-12T04:17:07.822+0000] {subprocess.py:93} INFO -   File "/home/***/.local/lib/python3.10/site-packages/pandas/io/common.py", line 863, in get_handle
[2025-07-12T04:17:07.822+0000] {subprocess.py:93} INFO -     handle = open(
[2025-07-12T04:17:07.822+0000] {subprocess.py:93} INFO - FileNotFoundError: [Errno 2] No such file or directory: '../Data/churn-data.csv'
[2025-07-12T04:17:08.128+0000] {subprocess.py:97} INFO - Command exited with return code 1
[2025-07-12T04:17:08.129+0000] {taskinstance.py:441} INFO - ::group::Post task execution logs
[2025-07-12T04:17:08.144+0000] {taskinstance.py:2905} ERROR - Task failed with exception
Traceback (most recent call last):
  File "/home/airflow/.local/lib/python3.10/site-packages/airflow/models/taskinstance.py", line 465, in _execute_task
    result = _execute_callable(context=context, **execute_callable_kwargs)
  File "/home/airflow/.local/lib/python3.10/site-packages/airflow/models/taskinstance.py", line 432, in _execute_callable
    return execute_callable(context=context, **execute_callable_kwargs)
  File "/home/airflow/.local/lib/python3.10/site-packages/airflow/models/baseoperator.py", line 400, in wrapper
    return func(self, *args, **kwargs)
  File "/home/airflow/.local/lib/python3.10/site-packages/airflow/operators/bash.py", line 243, in execute
    raise AirflowException(
airflow.exceptions.AirflowException: Bash command failed. The command returned a non-zero exit code 1.
[2025-07-12T04:17:08.150+0000] {taskinstance.py:1206} INFO - Marking task as FAILED. dag_id=ml_pipeline, task_id=training_task, run_id=scheduled__2025-07-11T00:00:00+00:00, execution_date=20250711T000000, start_date=20250712T041703, end_date=20250712T041708
[2025-07-12T04:17:08.170+0000] {standard_task_runner.py:110} ERROR - Failed to execute job 10 for task training_task (Bash command failed. The command returned a non-zero exit code 1.; 312)
[2025-07-12T04:17:08.196+0000] {local_task_job_runner.py:240} INFO - Task exited with return code 1
[2025-07-12T04:17:08.221+0000] {taskinstance.py:3498} INFO - 0 downstream tasks scheduled from follow-on schedule check
[2025-07-12T04:17:08.223+0000] {local_task_job_runner.py:222} INFO - ::endgroup::
