[2025-07-11T19:29:41.980+0000] {local_task_job_runner.py:120} INFO - ::group::Pre task execution logs
[2025-07-11T19:29:42.028+0000] {taskinstance.py:2076} INFO - Dependencies all met for dep_context=non-requeueable deps ti=<TaskInstance: ml_pipeline.training_task manual__2025-07-11T19:29:39.659366+00:00 [queued]>
[2025-07-11T19:29:42.042+0000] {taskinstance.py:2076} INFO - Dependencies all met for dep_context=requeueable deps ti=<TaskInstance: ml_pipeline.training_task manual__2025-07-11T19:29:39.659366+00:00 [queued]>
[2025-07-11T19:29:42.043+0000] {taskinstance.py:2306} INFO - Starting attempt 1 of 1
[2025-07-11T19:29:42.074+0000] {taskinstance.py:2330} INFO - Executing <Task(DockerOperator): training_task> on 2025-07-11 19:29:39.659366+00:00
[2025-07-11T19:29:42.084+0000] {standard_task_runner.py:63} INFO - Started process 257 to run task
[2025-07-11T19:29:42.089+0000] {standard_task_runner.py:90} INFO - Running: ['***', 'tasks', 'run', 'ml_pipeline', 'training_task', 'manual__2025-07-11T19:29:39.659366+00:00', '--job-id', '7', '--raw', '--subdir', 'DAGS_FOLDER/ml_pipeline.py', '--cfg-path', '/tmp/tmpo5uy1xo9']
[2025-07-11T19:29:42.091+0000] {standard_task_runner.py:91} INFO - Job 7: Subtask training_task
[2025-07-11T19:29:42.158+0000] {task_command.py:426} INFO - Running <TaskInstance: ml_pipeline.training_task manual__2025-07-11T19:29:39.659366+00:00 [running]> on host 9c8ac9649d23
[2025-07-11T19:29:42.276+0000] {taskinstance.py:2648} INFO - Exporting env vars: AIRFLOW_CTX_DAG_OWNER='Ebrahim Emad' AIRFLOW_CTX_DAG_ID='ml_pipeline' AIRFLOW_CTX_TASK_ID='training_task' AIRFLOW_CTX_EXECUTION_DATE='2025-07-11T19:29:39.659366+00:00' AIRFLOW_CTX_TRY_NUMBER='1' AIRFLOW_CTX_DAG_RUN_ID='manual__2025-07-11T19:29:39.659366+00:00'
[2025-07-11T19:29:42.277+0000] {taskinstance.py:430} INFO - ::endgroup::
[2025-07-11T19:29:42.329+0000] {docker.py:366} INFO - Starting docker container from image orchestration-scheduler:latest
[2025-07-11T19:29:42.334+0000] {taskinstance.py:441} INFO - ::group::Post task execution logs
[2025-07-11T19:29:42.335+0000] {taskinstance.py:2905} ERROR - Task failed with exception
Traceback (most recent call last):
  File "/home/airflow/.local/lib/python3.10/site-packages/docker/api/client.py", line 265, in _raise_for_status
    response.raise_for_status()
  File "/home/airflow/.local/lib/python3.10/site-packages/requests/models.py", line 1021, in raise_for_status
    raise HTTPError(http_error_msg, response=self)
requests.exceptions.HTTPError: 400 Client Error: Bad Request for url: http+docker://localhost/v1.51/containers/create

The above exception was the direct cause of the following exception:

Traceback (most recent call last):
  File "/home/airflow/.local/lib/python3.10/site-packages/airflow/models/taskinstance.py", line 465, in _execute_task
    result = _execute_callable(context=context, **execute_callable_kwargs)
  File "/home/airflow/.local/lib/python3.10/site-packages/airflow/models/taskinstance.py", line 432, in _execute_callable
    return execute_callable(context=context, **execute_callable_kwargs)
  File "/home/airflow/.local/lib/python3.10/site-packages/airflow/models/baseoperator.py", line 400, in wrapper
    return func(self, *args, **kwargs)
  File "/home/airflow/.local/lib/python3.10/site-packages/airflow/providers/docker/operators/docker.py", line 509, in execute
    return self._run_image()
  File "/home/airflow/.local/lib/python3.10/site-packages/airflow/providers/docker/operators/docker.py", line 371, in _run_image
    return self._run_image_with_mounts([*self.mounts, tmp_mount], add_tmp_variable=True)
  File "/home/airflow/.local/lib/python3.10/site-packages/airflow/providers/docker/operators/docker.py", line 398, in _run_image_with_mounts
    self.container = self.cli.create_container(
  File "/home/airflow/.local/lib/python3.10/site-packages/docker/api/container.py", line 439, in create_container
    return self.create_container_from_config(config, name, platform)
  File "/home/airflow/.local/lib/python3.10/site-packages/docker/api/container.py", line 456, in create_container_from_config
    return self._result(res, True)
  File "/home/airflow/.local/lib/python3.10/site-packages/docker/api/client.py", line 271, in _result
    self._raise_for_status(response)
  File "/home/airflow/.local/lib/python3.10/site-packages/docker/api/client.py", line 267, in _raise_for_status
    raise create_api_error_from_http_exception(e) from e
  File "/home/airflow/.local/lib/python3.10/site-packages/docker/errors.py", line 39, in create_api_error_from_http_exception
    raise cls(e, response=response, explanation=explanation) from e
docker.errors.APIError: 400 Client Error for http+docker://localhost/v1.51/containers/create: Bad Request ("invalid mount config for type "bind": invalid mount path: '../notebooks' mount path must be absolute")
[2025-07-11T19:29:42.348+0000] {taskinstance.py:1206} INFO - Marking task as FAILED. dag_id=ml_pipeline, task_id=training_task, run_id=manual__2025-07-11T19:29:39.659366+00:00, execution_date=20250711T192939, start_date=20250711T192942, end_date=20250711T192942
[2025-07-11T19:29:42.370+0000] {standard_task_runner.py:110} ERROR - Failed to execute job 7 for task training_task (400 Client Error for http+docker://localhost/v1.51/containers/create: Bad Request ("invalid mount config for type "bind": invalid mount path: '../notebooks' mount path must be absolute"); 257)
[2025-07-11T19:29:42.421+0000] {local_task_job_runner.py:240} INFO - Task exited with return code 1
[2025-07-11T19:29:42.446+0000] {taskinstance.py:3498} INFO - 0 downstream tasks scheduled from follow-on schedule check
[2025-07-11T19:29:42.451+0000] {local_task_job_runner.py:222} INFO - ::endgroup::
