[2025-07-11T19:27:30.597+0000] {local_task_job_runner.py:120} INFO - ::group::Pre task execution logs
[2025-07-11T19:27:30.639+0000] {taskinstance.py:2076} INFO - Dependencies all met for dep_context=non-requeueable deps ti=<TaskInstance: ml_pipeline.training_task manual__2025-07-11T19:27:27.996419+00:00 [queued]>
[2025-07-11T19:27:30.651+0000] {taskinstance.py:2076} INFO - Dependencies all met for dep_context=requeueable deps ti=<TaskInstance: ml_pipeline.training_task manual__2025-07-11T19:27:27.996419+00:00 [queued]>
[2025-07-11T19:27:30.651+0000] {taskinstance.py:2306} INFO - Starting attempt 1 of 1
[2025-07-11T19:27:30.669+0000] {taskinstance.py:2330} INFO - Executing <Task(DockerOperator): training_task> on 2025-07-11 19:27:27.996419+00:00
[2025-07-11T19:27:30.678+0000] {standard_task_runner.py:63} INFO - Started process 197 to run task
[2025-07-11T19:27:30.683+0000] {standard_task_runner.py:90} INFO - Running: ['***', 'tasks', 'run', 'ml_pipeline', 'training_task', 'manual__2025-07-11T19:27:27.996419+00:00', '--job-id', '3', '--raw', '--subdir', 'DAGS_FOLDER/ml_pipeline.py', '--cfg-path', '/tmp/tmp3olytbol']
[2025-07-11T19:27:30.685+0000] {standard_task_runner.py:91} INFO - Job 3: Subtask training_task
[2025-07-11T19:27:30.751+0000] {task_command.py:426} INFO - Running <TaskInstance: ml_pipeline.training_task manual__2025-07-11T19:27:27.996419+00:00 [running]> on host 9c8ac9649d23
[2025-07-11T19:27:30.867+0000] {taskinstance.py:2648} INFO - Exporting env vars: AIRFLOW_CTX_DAG_OWNER='Ebrahim Emad' AIRFLOW_CTX_DAG_ID='ml_pipeline' AIRFLOW_CTX_TASK_ID='training_task' AIRFLOW_CTX_EXECUTION_DATE='2025-07-11T19:27:27.996419+00:00' AIRFLOW_CTX_TRY_NUMBER='1' AIRFLOW_CTX_DAG_RUN_ID='manual__2025-07-11T19:27:27.996419+00:00'
[2025-07-11T19:27:30.868+0000] {taskinstance.py:430} INFO - ::endgroup::
[2025-07-11T19:27:30.922+0000] {docker.py:493} INFO - Pulling docker image orchestration_webserver
[2025-07-11T19:27:33.914+0000] {taskinstance.py:441} INFO - ::group::Post task execution logs
[2025-07-11T19:27:33.915+0000] {taskinstance.py:2905} ERROR - Task failed with exception
Traceback (most recent call last):
  File "/home/airflow/.local/lib/python3.10/site-packages/docker/api/client.py", line 265, in _raise_for_status
    response.raise_for_status()
  File "/home/airflow/.local/lib/python3.10/site-packages/requests/models.py", line 1021, in raise_for_status
    raise HTTPError(http_error_msg, response=self)
requests.exceptions.HTTPError: 404 Client Error: Not Found for url: http+docker://localhost/v1.51/images/create?tag=latest&fromImage=orchestration_webserver

The above exception was the direct cause of the following exception:

Traceback (most recent call last):
  File "/home/airflow/.local/lib/python3.10/site-packages/airflow/models/taskinstance.py", line 465, in _execute_task
    result = _execute_callable(context=context, **execute_callable_kwargs)
  File "/home/airflow/.local/lib/python3.10/site-packages/airflow/models/taskinstance.py", line 432, in _execute_callable
    return execute_callable(context=context, **execute_callable_kwargs)
  File "/home/airflow/.local/lib/python3.10/site-packages/airflow/models/baseoperator.py", line 400, in wrapper
    return func(self, *args, **kwargs)
  File "/home/airflow/.local/lib/python3.10/site-packages/airflow/providers/docker/operators/docker.py", line 495, in execute
    for output in self.cli.pull(self.image, stream=True, decode=True):
  File "/home/airflow/.local/lib/python3.10/site-packages/docker/api/image.py", line 429, in pull
    self._raise_for_status(response)
  File "/home/airflow/.local/lib/python3.10/site-packages/docker/api/client.py", line 267, in _raise_for_status
    raise create_api_error_from_http_exception(e) from e
  File "/home/airflow/.local/lib/python3.10/site-packages/docker/errors.py", line 39, in create_api_error_from_http_exception
    raise cls(e, response=response, explanation=explanation) from e
docker.errors.ImageNotFound: 404 Client Error for http+docker://localhost/v1.51/images/create?tag=latest&fromImage=orchestration_webserver: Not Found ("pull access denied for orchestration_webserver, repository does not exist or may require 'docker login': denied: requested access to the resource is denied")
[2025-07-11T19:27:33.930+0000] {taskinstance.py:1206} INFO - Marking task as FAILED. dag_id=ml_pipeline, task_id=training_task, run_id=manual__2025-07-11T19:27:27.996419+00:00, execution_date=20250711T192727, start_date=20250711T192730, end_date=20250711T192733
[2025-07-11T19:27:33.945+0000] {standard_task_runner.py:110} ERROR - Failed to execute job 3 for task training_task (404 Client Error for http+docker://localhost/v1.51/images/create?tag=latest&fromImage=orchestration_webserver: Not Found ("pull access denied for orchestration_webserver, repository does not exist or may require 'docker login': denied: requested access to the resource is denied"); 197)
[2025-07-11T19:27:33.986+0000] {local_task_job_runner.py:240} INFO - Task exited with return code 1
[2025-07-11T19:27:34.009+0000] {taskinstance.py:3498} INFO - 0 downstream tasks scheduled from follow-on schedule check
[2025-07-11T19:27:34.011+0000] {local_task_job_runner.py:222} INFO - ::endgroup::
